2024-07-03 10:42:41 | ERROR | __init__:exception:1524 | Job "providers_items_update (trigger: interval[0:00:10], next run at: 2024-07-03 10:42:51 MSK)" raised an exception
Traceback (most recent call last):

  File "c:\Users\club33\AppData\Local\Programs\Python\Python311\Lib\runpy.py", line 198, in _run_module_as_main
    return _run_code(code, main_globals, None,
           │         │     └ {'__name__': '__main__', '__doc__': None, '__package__': '', '__loader__': <_frozen_importlib_external.SourceFileLoader objec...
           │         └ <code object <module> at 0x00000290E429F890, file "c:\Users\club33\.vscode\extensions\ms-python.debugpy-2024.6.0-win32-x64\bu...
           └ <function _run_code at 0x00000290E445A160>
  File "c:\Users\club33\AppData\Local\Programs\Python\Python311\Lib\runpy.py", line 88, in _run_code
    exec(code, run_globals)
         │     └ {'__name__': '__main__', '__doc__': None, '__package__': '', '__loader__': <_frozen_importlib_external.SourceFileLoader objec...
         └ <code object <module> at 0x00000290E429F890, file "c:\Users\club33\.vscode\extensions\ms-python.debugpy-2024.6.0-win32-x64\bu...

  File "c:\Users\club33\.vscode\extensions\ms-python.debugpy-2024.6.0-win32-x64\bundled\libs\debugpy\adapter/../..\debugpy\launcher/../..\debugpy\__main__.py", line 39, in <module>
    cli.main()
    │   └ <function main at 0x00000290E6F52FC0>
    └ <module 'debugpy.server.cli' from 'c:\\Users\\club33\\.vscode\\extensions\\ms-python.debugpy-2024.6.0-win32-x64\\bundled\\lib...

  File "c:\Users\club33\.vscode\extensions\ms-python.debugpy-2024.6.0-win32-x64\bundled\libs\debugpy\adapter/../..\debugpy\launcher/../..\debugpy/..\debugpy\server\cli.py", line 430, in main
    run()
    └ <function run_file at 0x00000290E6F52D40>

  File "c:\Users\club33\.vscode\extensions\ms-python.debugpy-2024.6.0-win32-x64\bundled\libs\debugpy\adapter/../..\debugpy\launcher/../..\debugpy/..\debugpy\server\cli.py", line 284, in run_file
    runpy.run_path(target, run_name="__main__")
    │     │        └ 'C:\\Users\\club33\\Desktop\\RiseTGbot\\main.py'
    │     └ <function run_path at 0x00000290E6B6BF60>
    └ <module '_pydevd_bundle.pydevd_runpy' from 'c:\\Users\\club33\\.vscode\\extensions\\ms-python.debugpy-2024.6.0-win32-x64\\bun...

  File "c:\Users\club33\.vscode\extensions\ms-python.debugpy-2024.6.0-win32-x64\bundled\libs\debugpy\_vendored\pydevd\_pydevd_bundle\pydevd_runpy.py", line 321, in run_path
    return _run_module_code(code, init_globals, run_name,
           │                │     │             └ '__main__'
           │                │     └ None
           │                └ <code object <module> at 0x00000290E6F90990, file "C:\Users\club33\Desktop\RiseTGbot\main.py", line 1>
           └ <function _run_module_code at 0x00000290E6B6BBA0>

  File "c:\Users\club33\.vscode\extensions\ms-python.debugpy-2024.6.0-win32-x64\bundled\libs\debugpy\_vendored\pydevd\_pydevd_bundle\pydevd_runpy.py", line 135, in _run_module_code
    _run_code(code, mod_globals, init_globals,
    │         │     │            └ None
    │         │     └ {'__name__': '__main__', '__doc__': None, '__package__': '', '__loader__': None, '__spec__': None, '__file__': 'C:\\Users\\cl...
    │         └ <code object <module> at 0x00000290E6F90990, file "C:\Users\club33\Desktop\RiseTGbot\main.py", line 1>
    └ <function _run_code at 0x00000290E6B6B740>

  File "c:\Users\club33\.vscode\extensions\ms-python.debugpy-2024.6.0-win32-x64\bundled\libs\debugpy\_vendored\pydevd\_pydevd_bundle\pydevd_runpy.py", line 124, in _run_code
    exec(code, run_globals)
         │     └ {'__name__': '__main__', '__doc__': None, '__package__': '', '__loader__': None, '__spec__': None, '__file__': 'C:\\Users\\cl...
         └ <code object <module> at 0x00000290E6F90990, file "C:\Users\club33\Desktop\RiseTGbot\main.py", line 1>

  File "C:\Users\club33\Desktop\RiseTGbot\main.py", line 52, in <module>
    asyncio.run(main())
    │       │   └ <function main at 0x00000290F11393A0>
    │       └ <function run at 0x00000290E79600E0>
    └ <module 'asyncio' from 'c:\\Users\\club33\\AppData\\Local\\Programs\\Python\\Python311\\Lib\\asyncio\\__init__.py'>

  File "c:\Users\club33\AppData\Local\Programs\Python\Python311\Lib\asyncio\runners.py", line 190, in run
    return runner.run(main)
           │      │   └ <coroutine object main at 0x00000290E6FCBD30>
           │      └ <function Runner.run at 0x00000290E79D5D00>
           └ <asyncio.runners.Runner object at 0x00000290ECAB5790>
  File "c:\Users\club33\AppData\Local\Programs\Python\Python311\Lib\asyncio\runners.py", line 118, in run
    return self._loop.run_until_complete(task)
           │    │     │                  └ <Task pending name='Task-7' coro=<main() running at C:\Users\club33\Desktop\RiseTGbot\main.py:47> wait_for=<Future pending cb...
           │    │     └ <function BaseEventLoop.run_until_complete at 0x00000290E79CF600>
           │    └ <ProactorEventLoop running=True closed=False debug=False>
           └ <asyncio.runners.Runner object at 0x00000290ECAB5790>
  File "c:\Users\club33\AppData\Local\Programs\Python\Python311\Lib\asyncio\base_events.py", line 641, in run_until_complete
    self.run_forever()
    │    └ <function ProactorEventLoop.run_forever at 0x00000290E7A51E40>
    └ <ProactorEventLoop running=True closed=False debug=False>
  File "c:\Users\club33\AppData\Local\Programs\Python\Python311\Lib\asyncio\windows_events.py", line 321, in run_forever
    super().run_forever()
  File "c:\Users\club33\AppData\Local\Programs\Python\Python311\Lib\asyncio\base_events.py", line 608, in run_forever
    self._run_once()
    │    └ <function BaseEventLoop._run_once at 0x00000290E79D53A0>
    └ <ProactorEventLoop running=True closed=False debug=False>
  File "c:\Users\club33\AppData\Local\Programs\Python\Python311\Lib\asyncio\base_events.py", line 1936, in _run_once
    handle._run()
    │      └ <function Handle._run at 0x00000290E7900C20>
    └ <Handle Task.task_wakeup(<Future finished result=None>)>
  File "c:\Users\club33\AppData\Local\Programs\Python\Python311\Lib\asyncio\events.py", line 84, in _run
    self._context.run(self._callback, *self._args)
    │    │            │    │           │    └ <member '_args' of 'Handle' objects>
    │    │            │    │           └ <Handle Task.task_wakeup(<Future finished result=None>)>
    │    │            │    └ <member '_callback' of 'Handle' objects>
    │    │            └ <Handle Task.task_wakeup(<Future finished result=None>)>
    │    └ <member '_context' of 'Handle' objects>
    └ <Handle Task.task_wakeup(<Future finished result=None>)>
> File "c:\Users\club33\AppData\Local\Programs\Python\Python311\Lib\site-packages\apscheduler\executors\base_py3.py", line 30, in run_coroutine_job
    retval = await job.func(*job.args, **job.kwargs)
                   │   │     │   │       │   └ <member 'kwargs' of 'Job' objects>
                   │   │     │   │       └ <Job (id=69c6ed59e28a4ea1aa3485a2e4920658 name=providers_items_update)>
                   │   │     │   └ <member 'args' of 'Job' objects>
                   │   │     └ <Job (id=69c6ed59e28a4ea1aa3485a2e4920658 name=providers_items_update)>
                   │   └ <member 'func' of 'Job' objects>
                   └ <Job (id=69c6ed59e28a4ea1aa3485a2e4920658 name=providers_items_update)>

  File "C:\Users\club33\Desktop\RiseTGbot\bot\schedulers\providers_items_update.py", line 18, in providers_items_update
    pricing_providers = await _load_file('data/pricing_providers.json')
                              └ <function _load_file at 0x00000290F1139760>

  File "C:\Users\club33\Desktop\RiseTGbot\bot\schedulers\providers_items_update.py", line 31, in _load_file
    return orjson.loads(content)
           │      │     └ ''
           │      └ <built-in function loads>
           └ <module 'orjson' from 'c:\\Users\\club33\\AppData\\Local\\Programs\\Python\\Python311\\Lib\\site-packages\\orjson\\__init__.py'>

orjson.JSONDecodeError: Input is a zero-length, empty document: line 1 column 1 (char 0)
2024-07-03 10:42:51 | ERROR | __init__:exception:1524 | Job "providers_items_update (trigger: interval[0:00:10], next run at: 2024-07-03 10:43:01 MSK)" raised an exception
Traceback (most recent call last):

  File "c:\Users\club33\AppData\Local\Programs\Python\Python311\Lib\runpy.py", line 198, in _run_module_as_main
    return _run_code(code, main_globals, None,
           │         │     └ {'__name__': '__main__', '__doc__': None, '__package__': '', '__loader__': <_frozen_importlib_external.SourceFileLoader objec...
           │         └ <code object <module> at 0x00000290E429F890, file "c:\Users\club33\.vscode\extensions\ms-python.debugpy-2024.6.0-win32-x64\bu...
           └ <function _run_code at 0x00000290E445A160>
  File "c:\Users\club33\AppData\Local\Programs\Python\Python311\Lib\runpy.py", line 88, in _run_code
    exec(code, run_globals)
         │     └ {'__name__': '__main__', '__doc__': None, '__package__': '', '__loader__': <_frozen_importlib_external.SourceFileLoader objec...
         └ <code object <module> at 0x00000290E429F890, file "c:\Users\club33\.vscode\extensions\ms-python.debugpy-2024.6.0-win32-x64\bu...

  File "c:\Users\club33\.vscode\extensions\ms-python.debugpy-2024.6.0-win32-x64\bundled\libs\debugpy\adapter/../..\debugpy\launcher/../..\debugpy\__main__.py", line 39, in <module>
    cli.main()
    │   └ <function main at 0x00000290E6F52FC0>
    └ <module 'debugpy.server.cli' from 'c:\\Users\\club33\\.vscode\\extensions\\ms-python.debugpy-2024.6.0-win32-x64\\bundled\\lib...

  File "c:\Users\club33\.vscode\extensions\ms-python.debugpy-2024.6.0-win32-x64\bundled\libs\debugpy\adapter/../..\debugpy\launcher/../..\debugpy/..\debugpy\server\cli.py", line 430, in main
    run()
    └ <function run_file at 0x00000290E6F52D40>

  File "c:\Users\club33\.vscode\extensions\ms-python.debugpy-2024.6.0-win32-x64\bundled\libs\debugpy\adapter/../..\debugpy\launcher/../..\debugpy/..\debugpy\server\cli.py", line 284, in run_file
    runpy.run_path(target, run_name="__main__")
    │     │        └ 'C:\\Users\\club33\\Desktop\\RiseTGbot\\main.py'
    │     └ <function run_path at 0x00000290E6B6BF60>
    └ <module '_pydevd_bundle.pydevd_runpy' from 'c:\\Users\\club33\\.vscode\\extensions\\ms-python.debugpy-2024.6.0-win32-x64\\bun...

  File "c:\Users\club33\.vscode\extensions\ms-python.debugpy-2024.6.0-win32-x64\bundled\libs\debugpy\_vendored\pydevd\_pydevd_bundle\pydevd_runpy.py", line 321, in run_path
    return _run_module_code(code, init_globals, run_name,
           │                │     │             └ '__main__'
           │                │     └ None
           │                └ <code object <module> at 0x00000290E6F90990, file "C:\Users\club33\Desktop\RiseTGbot\main.py", line 1>
           └ <function _run_module_code at 0x00000290E6B6BBA0>

  File "c:\Users\club33\.vscode\extensions\ms-python.debugpy-2024.6.0-win32-x64\bundled\libs\debugpy\_vendored\pydevd\_pydevd_bundle\pydevd_runpy.py", line 135, in _run_module_code
    _run_code(code, mod_globals, init_globals,
    │         │     │            └ None
    │         │     └ {'__name__': '__main__', '__doc__': None, '__package__': '', '__loader__': None, '__spec__': None, '__file__': 'C:\\Users\\cl...
    │         └ <code object <module> at 0x00000290E6F90990, file "C:\Users\club33\Desktop\RiseTGbot\main.py", line 1>
    └ <function _run_code at 0x00000290E6B6B740>

  File "c:\Users\club33\.vscode\extensions\ms-python.debugpy-2024.6.0-win32-x64\bundled\libs\debugpy\_vendored\pydevd\_pydevd_bundle\pydevd_runpy.py", line 124, in _run_code
    exec(code, run_globals)
         │     └ {'__name__': '__main__', '__doc__': None, '__package__': '', '__loader__': None, '__spec__': None, '__file__': 'C:\\Users\\cl...
         └ <code object <module> at 0x00000290E6F90990, file "C:\Users\club33\Desktop\RiseTGbot\main.py", line 1>

  File "C:\Users\club33\Desktop\RiseTGbot\main.py", line 52, in <module>
    asyncio.run(main())
    │       │   └ <function main at 0x00000290F11393A0>
    │       └ <function run at 0x00000290E79600E0>
    └ <module 'asyncio' from 'c:\\Users\\club33\\AppData\\Local\\Programs\\Python\\Python311\\Lib\\asyncio\\__init__.py'>

  File "c:\Users\club33\AppData\Local\Programs\Python\Python311\Lib\asyncio\runners.py", line 190, in run
    return runner.run(main)
           │      │   └ <coroutine object main at 0x00000290E6FCBD30>
           │      └ <function Runner.run at 0x00000290E79D5D00>
           └ <asyncio.runners.Runner object at 0x00000290ECAB5790>
  File "c:\Users\club33\AppData\Local\Programs\Python\Python311\Lib\asyncio\runners.py", line 118, in run
    return self._loop.run_until_complete(task)
           │    │     │                  └ <Task pending name='Task-7' coro=<main() running at C:\Users\club33\Desktop\RiseTGbot\main.py:47> wait_for=<Future pending cb...
           │    │     └ <function BaseEventLoop.run_until_complete at 0x00000290E79CF600>
           │    └ <ProactorEventLoop running=True closed=False debug=False>
           └ <asyncio.runners.Runner object at 0x00000290ECAB5790>
  File "c:\Users\club33\AppData\Local\Programs\Python\Python311\Lib\asyncio\base_events.py", line 641, in run_until_complete
    self.run_forever()
    │    └ <function ProactorEventLoop.run_forever at 0x00000290E7A51E40>
    └ <ProactorEventLoop running=True closed=False debug=False>
  File "c:\Users\club33\AppData\Local\Programs\Python\Python311\Lib\asyncio\windows_events.py", line 321, in run_forever
    super().run_forever()
  File "c:\Users\club33\AppData\Local\Programs\Python\Python311\Lib\asyncio\base_events.py", line 608, in run_forever
    self._run_once()
    │    └ <function BaseEventLoop._run_once at 0x00000290E79D53A0>
    └ <ProactorEventLoop running=True closed=False debug=False>
  File "c:\Users\club33\AppData\Local\Programs\Python\Python311\Lib\asyncio\base_events.py", line 1936, in _run_once
    handle._run()
    │      └ <function Handle._run at 0x00000290E7900C20>
    └ <Handle Task.task_wakeup(<Future finished result=None>)>
  File "c:\Users\club33\AppData\Local\Programs\Python\Python311\Lib\asyncio\events.py", line 84, in _run
    self._context.run(self._callback, *self._args)
    │    │            │    │           │    └ <member '_args' of 'Handle' objects>
    │    │            │    │           └ <Handle Task.task_wakeup(<Future finished result=None>)>
    │    │            │    └ <member '_callback' of 'Handle' objects>
    │    │            └ <Handle Task.task_wakeup(<Future finished result=None>)>
    │    └ <member '_context' of 'Handle' objects>
    └ <Handle Task.task_wakeup(<Future finished result=None>)>
> File "c:\Users\club33\AppData\Local\Programs\Python\Python311\Lib\site-packages\apscheduler\executors\base_py3.py", line 30, in run_coroutine_job
    retval = await job.func(*job.args, **job.kwargs)
                   │   │     │   │       │   └ <member 'kwargs' of 'Job' objects>
                   │   │     │   │       └ <Job (id=69c6ed59e28a4ea1aa3485a2e4920658 name=providers_items_update)>
                   │   │     │   └ <member 'args' of 'Job' objects>
                   │   │     └ <Job (id=69c6ed59e28a4ea1aa3485a2e4920658 name=providers_items_update)>
                   │   └ <member 'func' of 'Job' objects>
                   └ <Job (id=69c6ed59e28a4ea1aa3485a2e4920658 name=providers_items_update)>

  File "C:\Users\club33\Desktop\RiseTGbot\bot\schedulers\providers_items_update.py", line 18, in providers_items_update
    pricing_providers = await _load_file('data/pricing_providers.json')
                              └ <function _load_file at 0x00000290F1139760>

  File "C:\Users\club33\Desktop\RiseTGbot\bot\schedulers\providers_items_update.py", line 31, in _load_file
    return orjson.loads(content)
           │      │     └ ''
           │      └ <built-in function loads>
           └ <module 'orjson' from 'c:\\Users\\club33\\AppData\\Local\\Programs\\Python\\Python311\\Lib\\site-packages\\orjson\\__init__.py'>

orjson.JSONDecodeError: Input is a zero-length, empty document: line 1 column 1 (char 0)
2024-07-03 10:43:01 | ERROR | __init__:exception:1524 | Job "providers_items_update (trigger: interval[0:00:10], next run at: 2024-07-03 10:43:11 MSK)" raised an exception
Traceback (most recent call last):

  File "c:\Users\club33\AppData\Local\Programs\Python\Python311\Lib\runpy.py", line 198, in _run_module_as_main
    return _run_code(code, main_globals, None,
           │         │     └ {'__name__': '__main__', '__doc__': None, '__package__': '', '__loader__': <_frozen_importlib_external.SourceFileLoader objec...
           │         └ <code object <module> at 0x00000290E429F890, file "c:\Users\club33\.vscode\extensions\ms-python.debugpy-2024.6.0-win32-x64\bu...
           └ <function _run_code at 0x00000290E445A160>
  File "c:\Users\club33\AppData\Local\Programs\Python\Python311\Lib\runpy.py", line 88, in _run_code
    exec(code, run_globals)
         │     └ {'__name__': '__main__', '__doc__': None, '__package__': '', '__loader__': <_frozen_importlib_external.SourceFileLoader objec...
         └ <code object <module> at 0x00000290E429F890, file "c:\Users\club33\.vscode\extensions\ms-python.debugpy-2024.6.0-win32-x64\bu...

  File "c:\Users\club33\.vscode\extensions\ms-python.debugpy-2024.6.0-win32-x64\bundled\libs\debugpy\adapter/../..\debugpy\launcher/../..\debugpy\__main__.py", line 39, in <module>
    cli.main()
    │   └ <function main at 0x00000290E6F52FC0>
    └ <module 'debugpy.server.cli' from 'c:\\Users\\club33\\.vscode\\extensions\\ms-python.debugpy-2024.6.0-win32-x64\\bundled\\lib...

  File "c:\Users\club33\.vscode\extensions\ms-python.debugpy-2024.6.0-win32-x64\bundled\libs\debugpy\adapter/../..\debugpy\launcher/../..\debugpy/..\debugpy\server\cli.py", line 430, in main
    run()
    └ <function run_file at 0x00000290E6F52D40>

  File "c:\Users\club33\.vscode\extensions\ms-python.debugpy-2024.6.0-win32-x64\bundled\libs\debugpy\adapter/../..\debugpy\launcher/../..\debugpy/..\debugpy\server\cli.py", line 284, in run_file
    runpy.run_path(target, run_name="__main__")
    │     │        └ 'C:\\Users\\club33\\Desktop\\RiseTGbot\\main.py'
    │     └ <function run_path at 0x00000290E6B6BF60>
    └ <module '_pydevd_bundle.pydevd_runpy' from 'c:\\Users\\club33\\.vscode\\extensions\\ms-python.debugpy-2024.6.0-win32-x64\\bun...

  File "c:\Users\club33\.vscode\extensions\ms-python.debugpy-2024.6.0-win32-x64\bundled\libs\debugpy\_vendored\pydevd\_pydevd_bundle\pydevd_runpy.py", line 321, in run_path
    return _run_module_code(code, init_globals, run_name,
           │                │     │             └ '__main__'
           │                │     └ None
           │                └ <code object <module> at 0x00000290E6F90990, file "C:\Users\club33\Desktop\RiseTGbot\main.py", line 1>
           └ <function _run_module_code at 0x00000290E6B6BBA0>

  File "c:\Users\club33\.vscode\extensions\ms-python.debugpy-2024.6.0-win32-x64\bundled\libs\debugpy\_vendored\pydevd\_pydevd_bundle\pydevd_runpy.py", line 135, in _run_module_code
    _run_code(code, mod_globals, init_globals,
    │         │     │            └ None
    │         │     └ {'__name__': '__main__', '__doc__': None, '__package__': '', '__loader__': None, '__spec__': None, '__file__': 'C:\\Users\\cl...
    │         └ <code object <module> at 0x00000290E6F90990, file "C:\Users\club33\Desktop\RiseTGbot\main.py", line 1>
    └ <function _run_code at 0x00000290E6B6B740>

  File "c:\Users\club33\.vscode\extensions\ms-python.debugpy-2024.6.0-win32-x64\bundled\libs\debugpy\_vendored\pydevd\_pydevd_bundle\pydevd_runpy.py", line 124, in _run_code
    exec(code, run_globals)
         │     └ {'__name__': '__main__', '__doc__': None, '__package__': '', '__loader__': None, '__spec__': None, '__file__': 'C:\\Users\\cl...
         └ <code object <module> at 0x00000290E6F90990, file "C:\Users\club33\Desktop\RiseTGbot\main.py", line 1>

  File "C:\Users\club33\Desktop\RiseTGbot\main.py", line 52, in <module>
    asyncio.run(main())
    │       │   └ <function main at 0x00000290F11393A0>
    │       └ <function run at 0x00000290E79600E0>
    └ <module 'asyncio' from 'c:\\Users\\club33\\AppData\\Local\\Programs\\Python\\Python311\\Lib\\asyncio\\__init__.py'>

  File "c:\Users\club33\AppData\Local\Programs\Python\Python311\Lib\asyncio\runners.py", line 190, in run
    return runner.run(main)
           │      │   └ <coroutine object main at 0x00000290E6FCBD30>
           │      └ <function Runner.run at 0x00000290E79D5D00>
           └ <asyncio.runners.Runner object at 0x00000290ECAB5790>
  File "c:\Users\club33\AppData\Local\Programs\Python\Python311\Lib\asyncio\runners.py", line 118, in run
    return self._loop.run_until_complete(task)
           │    │     │                  └ <Task pending name='Task-7' coro=<main() running at C:\Users\club33\Desktop\RiseTGbot\main.py:47> wait_for=<Future pending cb...
           │    │     └ <function BaseEventLoop.run_until_complete at 0x00000290E79CF600>
           │    └ <ProactorEventLoop running=True closed=False debug=False>
           └ <asyncio.runners.Runner object at 0x00000290ECAB5790>
  File "c:\Users\club33\AppData\Local\Programs\Python\Python311\Lib\asyncio\base_events.py", line 641, in run_until_complete
    self.run_forever()
    │    └ <function ProactorEventLoop.run_forever at 0x00000290E7A51E40>
    └ <ProactorEventLoop running=True closed=False debug=False>
  File "c:\Users\club33\AppData\Local\Programs\Python\Python311\Lib\asyncio\windows_events.py", line 321, in run_forever
    super().run_forever()
  File "c:\Users\club33\AppData\Local\Programs\Python\Python311\Lib\asyncio\base_events.py", line 608, in run_forever
    self._run_once()
    │    └ <function BaseEventLoop._run_once at 0x00000290E79D53A0>
    └ <ProactorEventLoop running=True closed=False debug=False>
  File "c:\Users\club33\AppData\Local\Programs\Python\Python311\Lib\asyncio\base_events.py", line 1936, in _run_once
    handle._run()
    │      └ <function Handle._run at 0x00000290E7900C20>
    └ <Handle Task.task_wakeup(<Future finished result=None>)>
  File "c:\Users\club33\AppData\Local\Programs\Python\Python311\Lib\asyncio\events.py", line 84, in _run
    self._context.run(self._callback, *self._args)
    │    │            │    │           │    └ <member '_args' of 'Handle' objects>
    │    │            │    │           └ <Handle Task.task_wakeup(<Future finished result=None>)>
    │    │            │    └ <member '_callback' of 'Handle' objects>
    │    │            └ <Handle Task.task_wakeup(<Future finished result=None>)>
    │    └ <member '_context' of 'Handle' objects>
    └ <Handle Task.task_wakeup(<Future finished result=None>)>
> File "c:\Users\club33\AppData\Local\Programs\Python\Python311\Lib\site-packages\apscheduler\executors\base_py3.py", line 30, in run_coroutine_job
    retval = await job.func(*job.args, **job.kwargs)
                   │   │     │   │       │   └ <member 'kwargs' of 'Job' objects>
                   │   │     │   │       └ <Job (id=69c6ed59e28a4ea1aa3485a2e4920658 name=providers_items_update)>
                   │   │     │   └ <member 'args' of 'Job' objects>
                   │   │     └ <Job (id=69c6ed59e28a4ea1aa3485a2e4920658 name=providers_items_update)>
                   │   └ <member 'func' of 'Job' objects>
                   └ <Job (id=69c6ed59e28a4ea1aa3485a2e4920658 name=providers_items_update)>

  File "C:\Users\club33\Desktop\RiseTGbot\bot\schedulers\providers_items_update.py", line 18, in providers_items_update
    pricing_providers = await _load_file('data/pricing_providers.json')
                              └ <function _load_file at 0x00000290F1139760>

  File "C:\Users\club33\Desktop\RiseTGbot\bot\schedulers\providers_items_update.py", line 31, in _load_file
    return orjson.loads(content)
           │      │     └ ''
           │      └ <built-in function loads>
           └ <module 'orjson' from 'c:\\Users\\club33\\AppData\\Local\\Programs\\Python\\Python311\\Lib\\site-packages\\orjson\\__init__.py'>

orjson.JSONDecodeError: Input is a zero-length, empty document: line 1 column 1 (char 0)
2024-07-03 10:43:11 | ERROR | __init__:exception:1524 | Job "providers_items_update (trigger: interval[0:00:10], next run at: 2024-07-03 10:43:21 MSK)" raised an exception
Traceback (most recent call last):

  File "c:\Users\club33\AppData\Local\Programs\Python\Python311\Lib\runpy.py", line 198, in _run_module_as_main
    return _run_code(code, main_globals, None,
           │         │     └ {'__name__': '__main__', '__doc__': None, '__package__': '', '__loader__': <_frozen_importlib_external.SourceFileLoader objec...
           │         └ <code object <module> at 0x00000290E429F890, file "c:\Users\club33\.vscode\extensions\ms-python.debugpy-2024.6.0-win32-x64\bu...
           └ <function _run_code at 0x00000290E445A160>
  File "c:\Users\club33\AppData\Local\Programs\Python\Python311\Lib\runpy.py", line 88, in _run_code
    exec(code, run_globals)
         │     └ {'__name__': '__main__', '__doc__': None, '__package__': '', '__loader__': <_frozen_importlib_external.SourceFileLoader objec...
         └ <code object <module> at 0x00000290E429F890, file "c:\Users\club33\.vscode\extensions\ms-python.debugpy-2024.6.0-win32-x64\bu...

  File "c:\Users\club33\.vscode\extensions\ms-python.debugpy-2024.6.0-win32-x64\bundled\libs\debugpy\adapter/../..\debugpy\launcher/../..\debugpy\__main__.py", line 39, in <module>
    cli.main()
    │   └ <function main at 0x00000290E6F52FC0>
    └ <module 'debugpy.server.cli' from 'c:\\Users\\club33\\.vscode\\extensions\\ms-python.debugpy-2024.6.0-win32-x64\\bundled\\lib...

  File "c:\Users\club33\.vscode\extensions\ms-python.debugpy-2024.6.0-win32-x64\bundled\libs\debugpy\adapter/../..\debugpy\launcher/../..\debugpy/..\debugpy\server\cli.py", line 430, in main
    run()
    └ <function run_file at 0x00000290E6F52D40>

  File "c:\Users\club33\.vscode\extensions\ms-python.debugpy-2024.6.0-win32-x64\bundled\libs\debugpy\adapter/../..\debugpy\launcher/../..\debugpy/..\debugpy\server\cli.py", line 284, in run_file
    runpy.run_path(target, run_name="__main__")
    │     │        └ 'C:\\Users\\club33\\Desktop\\RiseTGbot\\main.py'
    │     └ <function run_path at 0x00000290E6B6BF60>
    └ <module '_pydevd_bundle.pydevd_runpy' from 'c:\\Users\\club33\\.vscode\\extensions\\ms-python.debugpy-2024.6.0-win32-x64\\bun...

  File "c:\Users\club33\.vscode\extensions\ms-python.debugpy-2024.6.0-win32-x64\bundled\libs\debugpy\_vendored\pydevd\_pydevd_bundle\pydevd_runpy.py", line 321, in run_path
    return _run_module_code(code, init_globals, run_name,
           │                │     │             └ '__main__'
           │                │     └ None
           │                └ <code object <module> at 0x00000290E6F90990, file "C:\Users\club33\Desktop\RiseTGbot\main.py", line 1>
           └ <function _run_module_code at 0x00000290E6B6BBA0>

  File "c:\Users\club33\.vscode\extensions\ms-python.debugpy-2024.6.0-win32-x64\bundled\libs\debugpy\_vendored\pydevd\_pydevd_bundle\pydevd_runpy.py", line 135, in _run_module_code
    _run_code(code, mod_globals, init_globals,
    │         │     │            └ None
    │         │     └ {'__name__': '__main__', '__doc__': None, '__package__': '', '__loader__': None, '__spec__': None, '__file__': 'C:\\Users\\cl...
    │         └ <code object <module> at 0x00000290E6F90990, file "C:\Users\club33\Desktop\RiseTGbot\main.py", line 1>
    └ <function _run_code at 0x00000290E6B6B740>

  File "c:\Users\club33\.vscode\extensions\ms-python.debugpy-2024.6.0-win32-x64\bundled\libs\debugpy\_vendored\pydevd\_pydevd_bundle\pydevd_runpy.py", line 124, in _run_code
    exec(code, run_globals)
         │     └ {'__name__': '__main__', '__doc__': None, '__package__': '', '__loader__': None, '__spec__': None, '__file__': 'C:\\Users\\cl...
         └ <code object <module> at 0x00000290E6F90990, file "C:\Users\club33\Desktop\RiseTGbot\main.py", line 1>

  File "C:\Users\club33\Desktop\RiseTGbot\main.py", line 52, in <module>
    asyncio.run(main())
    │       │   └ <function main at 0x00000290F11393A0>
    │       └ <function run at 0x00000290E79600E0>
    └ <module 'asyncio' from 'c:\\Users\\club33\\AppData\\Local\\Programs\\Python\\Python311\\Lib\\asyncio\\__init__.py'>

  File "c:\Users\club33\AppData\Local\Programs\Python\Python311\Lib\asyncio\runners.py", line 190, in run
    return runner.run(main)
           │      │   └ <coroutine object main at 0x00000290E6FCBD30>
           │      └ <function Runner.run at 0x00000290E79D5D00>
           └ <asyncio.runners.Runner object at 0x00000290ECAB5790>
  File "c:\Users\club33\AppData\Local\Programs\Python\Python311\Lib\asyncio\runners.py", line 118, in run
    return self._loop.run_until_complete(task)
           │    │     │                  └ <Task pending name='Task-7' coro=<main() running at C:\Users\club33\Desktop\RiseTGbot\main.py:47> wait_for=<Future pending cb...
           │    │     └ <function BaseEventLoop.run_until_complete at 0x00000290E79CF600>
           │    └ <ProactorEventLoop running=True closed=False debug=False>
           └ <asyncio.runners.Runner object at 0x00000290ECAB5790>
  File "c:\Users\club33\AppData\Local\Programs\Python\Python311\Lib\asyncio\base_events.py", line 641, in run_until_complete
    self.run_forever()
    │    └ <function ProactorEventLoop.run_forever at 0x00000290E7A51E40>
    └ <ProactorEventLoop running=True closed=False debug=False>
  File "c:\Users\club33\AppData\Local\Programs\Python\Python311\Lib\asyncio\windows_events.py", line 321, in run_forever
    super().run_forever()
  File "c:\Users\club33\AppData\Local\Programs\Python\Python311\Lib\asyncio\base_events.py", line 608, in run_forever
    self._run_once()
    │    └ <function BaseEventLoop._run_once at 0x00000290E79D53A0>
    └ <ProactorEventLoop running=True closed=False debug=False>
  File "c:\Users\club33\AppData\Local\Programs\Python\Python311\Lib\asyncio\base_events.py", line 1936, in _run_once
    handle._run()
    │      └ <function Handle._run at 0x00000290E7900C20>
    └ <Handle Task.task_wakeup(<Future finished result=None>)>
  File "c:\Users\club33\AppData\Local\Programs\Python\Python311\Lib\asyncio\events.py", line 84, in _run
    self._context.run(self._callback, *self._args)
    │    │            │    │           │    └ <member '_args' of 'Handle' objects>
    │    │            │    │           └ <Handle Task.task_wakeup(<Future finished result=None>)>
    │    │            │    └ <member '_callback' of 'Handle' objects>
    │    │            └ <Handle Task.task_wakeup(<Future finished result=None>)>
    │    └ <member '_context' of 'Handle' objects>
    └ <Handle Task.task_wakeup(<Future finished result=None>)>
> File "c:\Users\club33\AppData\Local\Programs\Python\Python311\Lib\site-packages\apscheduler\executors\base_py3.py", line 30, in run_coroutine_job
    retval = await job.func(*job.args, **job.kwargs)
                   │   │     │   │       │   └ <member 'kwargs' of 'Job' objects>
                   │   │     │   │       └ <Job (id=69c6ed59e28a4ea1aa3485a2e4920658 name=providers_items_update)>
                   │   │     │   └ <member 'args' of 'Job' objects>
                   │   │     └ <Job (id=69c6ed59e28a4ea1aa3485a2e4920658 name=providers_items_update)>
                   │   └ <member 'func' of 'Job' objects>
                   └ <Job (id=69c6ed59e28a4ea1aa3485a2e4920658 name=providers_items_update)>

  File "C:\Users\club33\Desktop\RiseTGbot\bot\schedulers\providers_items_update.py", line 18, in providers_items_update
    pricing_providers = await _load_file('data/pricing_providers.json')
                              └ <function _load_file at 0x00000290F1139760>

  File "C:\Users\club33\Desktop\RiseTGbot\bot\schedulers\providers_items_update.py", line 31, in _load_file
    return orjson.loads(content)
           │      │     └ ''
           │      └ <built-in function loads>
           └ <module 'orjson' from 'c:\\Users\\club33\\AppData\\Local\\Programs\\Python\\Python311\\Lib\\site-packages\\orjson\\__init__.py'>

orjson.JSONDecodeError: Input is a zero-length, empty document: line 1 column 1 (char 0)
2024-07-03 10:43:21 | ERROR | __init__:exception:1524 | Job "providers_items_update (trigger: interval[0:00:10], next run at: 2024-07-03 10:43:31 MSK)" raised an exception
Traceback (most recent call last):

  File "c:\Users\club33\AppData\Local\Programs\Python\Python311\Lib\runpy.py", line 198, in _run_module_as_main
    return _run_code(code, main_globals, None,
           │         │     └ {'__name__': '__main__', '__doc__': None, '__package__': '', '__loader__': <_frozen_importlib_external.SourceFileLoader objec...
           │         └ <code object <module> at 0x00000290E429F890, file "c:\Users\club33\.vscode\extensions\ms-python.debugpy-2024.6.0-win32-x64\bu...
           └ <function _run_code at 0x00000290E445A160>
  File "c:\Users\club33\AppData\Local\Programs\Python\Python311\Lib\runpy.py", line 88, in _run_code
    exec(code, run_globals)
         │     └ {'__name__': '__main__', '__doc__': None, '__package__': '', '__loader__': <_frozen_importlib_external.SourceFileLoader objec...
         └ <code object <module> at 0x00000290E429F890, file "c:\Users\club33\.vscode\extensions\ms-python.debugpy-2024.6.0-win32-x64\bu...

  File "c:\Users\club33\.vscode\extensions\ms-python.debugpy-2024.6.0-win32-x64\bundled\libs\debugpy\adapter/../..\debugpy\launcher/../..\debugpy\__main__.py", line 39, in <module>
    cli.main()
    │   └ <function main at 0x00000290E6F52FC0>
    └ <module 'debugpy.server.cli' from 'c:\\Users\\club33\\.vscode\\extensions\\ms-python.debugpy-2024.6.0-win32-x64\\bundled\\lib...

  File "c:\Users\club33\.vscode\extensions\ms-python.debugpy-2024.6.0-win32-x64\bundled\libs\debugpy\adapter/../..\debugpy\launcher/../..\debugpy/..\debugpy\server\cli.py", line 430, in main
    run()
    └ <function run_file at 0x00000290E6F52D40>

  File "c:\Users\club33\.vscode\extensions\ms-python.debugpy-2024.6.0-win32-x64\bundled\libs\debugpy\adapter/../..\debugpy\launcher/../..\debugpy/..\debugpy\server\cli.py", line 284, in run_file
    runpy.run_path(target, run_name="__main__")
    │     │        └ 'C:\\Users\\club33\\Desktop\\RiseTGbot\\main.py'
    │     └ <function run_path at 0x00000290E6B6BF60>
    └ <module '_pydevd_bundle.pydevd_runpy' from 'c:\\Users\\club33\\.vscode\\extensions\\ms-python.debugpy-2024.6.0-win32-x64\\bun...

  File "c:\Users\club33\.vscode\extensions\ms-python.debugpy-2024.6.0-win32-x64\bundled\libs\debugpy\_vendored\pydevd\_pydevd_bundle\pydevd_runpy.py", line 321, in run_path
    return _run_module_code(code, init_globals, run_name,
           │                │     │             └ '__main__'
           │                │     └ None
           │                └ <code object <module> at 0x00000290E6F90990, file "C:\Users\club33\Desktop\RiseTGbot\main.py", line 1>
           └ <function _run_module_code at 0x00000290E6B6BBA0>

  File "c:\Users\club33\.vscode\extensions\ms-python.debugpy-2024.6.0-win32-x64\bundled\libs\debugpy\_vendored\pydevd\_pydevd_bundle\pydevd_runpy.py", line 135, in _run_module_code
    _run_code(code, mod_globals, init_globals,
    │         │     │            └ None
    │         │     └ {'__name__': '__main__', '__doc__': None, '__package__': '', '__loader__': None, '__spec__': None, '__file__': 'C:\\Users\\cl...
    │         └ <code object <module> at 0x00000290E6F90990, file "C:\Users\club33\Desktop\RiseTGbot\main.py", line 1>
    └ <function _run_code at 0x00000290E6B6B740>

  File "c:\Users\club33\.vscode\extensions\ms-python.debugpy-2024.6.0-win32-x64\bundled\libs\debugpy\_vendored\pydevd\_pydevd_bundle\pydevd_runpy.py", line 124, in _run_code
    exec(code, run_globals)
         │     └ {'__name__': '__main__', '__doc__': None, '__package__': '', '__loader__': None, '__spec__': None, '__file__': 'C:\\Users\\cl...
         └ <code object <module> at 0x00000290E6F90990, file "C:\Users\club33\Desktop\RiseTGbot\main.py", line 1>

  File "C:\Users\club33\Desktop\RiseTGbot\main.py", line 52, in <module>
    asyncio.run(main())
    │       │   └ <function main at 0x00000290F11393A0>
    │       └ <function run at 0x00000290E79600E0>
    └ <module 'asyncio' from 'c:\\Users\\club33\\AppData\\Local\\Programs\\Python\\Python311\\Lib\\asyncio\\__init__.py'>

  File "c:\Users\club33\AppData\Local\Programs\Python\Python311\Lib\asyncio\runners.py", line 190, in run
    return runner.run(main)
           │      │   └ <coroutine object main at 0x00000290E6FCBD30>
           │      └ <function Runner.run at 0x00000290E79D5D00>
           └ <asyncio.runners.Runner object at 0x00000290ECAB5790>
  File "c:\Users\club33\AppData\Local\Programs\Python\Python311\Lib\asyncio\runners.py", line 118, in run
    return self._loop.run_until_complete(task)
           │    │     │                  └ <Task pending name='Task-7' coro=<main() running at C:\Users\club33\Desktop\RiseTGbot\main.py:47> wait_for=<Future pending cb...
           │    │     └ <function BaseEventLoop.run_until_complete at 0x00000290E79CF600>
           │    └ <ProactorEventLoop running=True closed=False debug=False>
           └ <asyncio.runners.Runner object at 0x00000290ECAB5790>
  File "c:\Users\club33\AppData\Local\Programs\Python\Python311\Lib\asyncio\base_events.py", line 641, in run_until_complete
    self.run_forever()
    │    └ <function ProactorEventLoop.run_forever at 0x00000290E7A51E40>
    └ <ProactorEventLoop running=True closed=False debug=False>
  File "c:\Users\club33\AppData\Local\Programs\Python\Python311\Lib\asyncio\windows_events.py", line 321, in run_forever
    super().run_forever()
  File "c:\Users\club33\AppData\Local\Programs\Python\Python311\Lib\asyncio\base_events.py", line 608, in run_forever
    self._run_once()
    │    └ <function BaseEventLoop._run_once at 0x00000290E79D53A0>
    └ <ProactorEventLoop running=True closed=False debug=False>
  File "c:\Users\club33\AppData\Local\Programs\Python\Python311\Lib\asyncio\base_events.py", line 1936, in _run_once
    handle._run()
    │      └ <function Handle._run at 0x00000290E7900C20>
    └ <Handle Task.task_wakeup(<Future finished result=None>)>
  File "c:\Users\club33\AppData\Local\Programs\Python\Python311\Lib\asyncio\events.py", line 84, in _run
    self._context.run(self._callback, *self._args)
    │    │            │    │           │    └ <member '_args' of 'Handle' objects>
    │    │            │    │           └ <Handle Task.task_wakeup(<Future finished result=None>)>
    │    │            │    └ <member '_callback' of 'Handle' objects>
    │    │            └ <Handle Task.task_wakeup(<Future finished result=None>)>
    │    └ <member '_context' of 'Handle' objects>
    └ <Handle Task.task_wakeup(<Future finished result=None>)>
> File "c:\Users\club33\AppData\Local\Programs\Python\Python311\Lib\site-packages\apscheduler\executors\base_py3.py", line 30, in run_coroutine_job
    retval = await job.func(*job.args, **job.kwargs)
                   │   │     │   │       │   └ <member 'kwargs' of 'Job' objects>
                   │   │     │   │       └ <Job (id=69c6ed59e28a4ea1aa3485a2e4920658 name=providers_items_update)>
                   │   │     │   └ <member 'args' of 'Job' objects>
                   │   │     └ <Job (id=69c6ed59e28a4ea1aa3485a2e4920658 name=providers_items_update)>
                   │   └ <member 'func' of 'Job' objects>
                   └ <Job (id=69c6ed59e28a4ea1aa3485a2e4920658 name=providers_items_update)>

  File "C:\Users\club33\Desktop\RiseTGbot\bot\schedulers\providers_items_update.py", line 18, in providers_items_update
    pricing_providers = await _load_file('data/pricing_providers.json')
                              └ <function _load_file at 0x00000290F1139760>

  File "C:\Users\club33\Desktop\RiseTGbot\bot\schedulers\providers_items_update.py", line 31, in _load_file
    return orjson.loads(content)
           │      │     └ ''
           │      └ <built-in function loads>
           └ <module 'orjson' from 'c:\\Users\\club33\\AppData\\Local\\Programs\\Python\\Python311\\Lib\\site-packages\\orjson\\__init__.py'>

orjson.JSONDecodeError: Input is a zero-length, empty document: line 1 column 1 (char 0)
2024-07-03 10:43:31 | ERROR | __init__:exception:1524 | Job "providers_items_update (trigger: interval[0:00:10], next run at: 2024-07-03 10:43:41 MSK)" raised an exception
Traceback (most recent call last):

  File "c:\Users\club33\AppData\Local\Programs\Python\Python311\Lib\runpy.py", line 198, in _run_module_as_main
    return _run_code(code, main_globals, None,
           │         │     └ {'__name__': '__main__', '__doc__': None, '__package__': '', '__loader__': <_frozen_importlib_external.SourceFileLoader objec...
           │         └ <code object <module> at 0x00000290E429F890, file "c:\Users\club33\.vscode\extensions\ms-python.debugpy-2024.6.0-win32-x64\bu...
           └ <function _run_code at 0x00000290E445A160>
  File "c:\Users\club33\AppData\Local\Programs\Python\Python311\Lib\runpy.py", line 88, in _run_code
    exec(code, run_globals)
         │     └ {'__name__': '__main__', '__doc__': None, '__package__': '', '__loader__': <_frozen_importlib_external.SourceFileLoader objec...
         └ <code object <module> at 0x00000290E429F890, file "c:\Users\club33\.vscode\extensions\ms-python.debugpy-2024.6.0-win32-x64\bu...

  File "c:\Users\club33\.vscode\extensions\ms-python.debugpy-2024.6.0-win32-x64\bundled\libs\debugpy\adapter/../..\debugpy\launcher/../..\debugpy\__main__.py", line 39, in <module>
    cli.main()
    │   └ <function main at 0x00000290E6F52FC0>
    └ <module 'debugpy.server.cli' from 'c:\\Users\\club33\\.vscode\\extensions\\ms-python.debugpy-2024.6.0-win32-x64\\bundled\\lib...

  File "c:\Users\club33\.vscode\extensions\ms-python.debugpy-2024.6.0-win32-x64\bundled\libs\debugpy\adapter/../..\debugpy\launcher/../..\debugpy/..\debugpy\server\cli.py", line 430, in main
    run()
    └ <function run_file at 0x00000290E6F52D40>

  File "c:\Users\club33\.vscode\extensions\ms-python.debugpy-2024.6.0-win32-x64\bundled\libs\debugpy\adapter/../..\debugpy\launcher/../..\debugpy/..\debugpy\server\cli.py", line 284, in run_file
    runpy.run_path(target, run_name="__main__")
    │     │        └ 'C:\\Users\\club33\\Desktop\\RiseTGbot\\main.py'
    │     └ <function run_path at 0x00000290E6B6BF60>
    └ <module '_pydevd_bundle.pydevd_runpy' from 'c:\\Users\\club33\\.vscode\\extensions\\ms-python.debugpy-2024.6.0-win32-x64\\bun...

  File "c:\Users\club33\.vscode\extensions\ms-python.debugpy-2024.6.0-win32-x64\bundled\libs\debugpy\_vendored\pydevd\_pydevd_bundle\pydevd_runpy.py", line 321, in run_path
    return _run_module_code(code, init_globals, run_name,
           │                │     │             └ '__main__'
           │                │     └ None
           │                └ <code object <module> at 0x00000290E6F90990, file "C:\Users\club33\Desktop\RiseTGbot\main.py", line 1>
           └ <function _run_module_code at 0x00000290E6B6BBA0>

  File "c:\Users\club33\.vscode\extensions\ms-python.debugpy-2024.6.0-win32-x64\bundled\libs\debugpy\_vendored\pydevd\_pydevd_bundle\pydevd_runpy.py", line 135, in _run_module_code
    _run_code(code, mod_globals, init_globals,
    │         │     │            └ None
    │         │     └ {'__name__': '__main__', '__doc__': None, '__package__': '', '__loader__': None, '__spec__': None, '__file__': 'C:\\Users\\cl...
    │         └ <code object <module> at 0x00000290E6F90990, file "C:\Users\club33\Desktop\RiseTGbot\main.py", line 1>
    └ <function _run_code at 0x00000290E6B6B740>

  File "c:\Users\club33\.vscode\extensions\ms-python.debugpy-2024.6.0-win32-x64\bundled\libs\debugpy\_vendored\pydevd\_pydevd_bundle\pydevd_runpy.py", line 124, in _run_code
    exec(code, run_globals)
         │     └ {'__name__': '__main__', '__doc__': None, '__package__': '', '__loader__': None, '__spec__': None, '__file__': 'C:\\Users\\cl...
         └ <code object <module> at 0x00000290E6F90990, file "C:\Users\club33\Desktop\RiseTGbot\main.py", line 1>

  File "C:\Users\club33\Desktop\RiseTGbot\main.py", line 52, in <module>
    asyncio.run(main())
    │       │   └ <function main at 0x00000290F11393A0>
    │       └ <function run at 0x00000290E79600E0>
    └ <module 'asyncio' from 'c:\\Users\\club33\\AppData\\Local\\Programs\\Python\\Python311\\Lib\\asyncio\\__init__.py'>

  File "c:\Users\club33\AppData\Local\Programs\Python\Python311\Lib\asyncio\runners.py", line 190, in run
    return runner.run(main)
           │      │   └ <coroutine object main at 0x00000290E6FCBD30>
           │      └ <function Runner.run at 0x00000290E79D5D00>
           └ <asyncio.runners.Runner object at 0x00000290ECAB5790>
  File "c:\Users\club33\AppData\Local\Programs\Python\Python311\Lib\asyncio\runners.py", line 118, in run
    return self._loop.run_until_complete(task)
           │    │     │                  └ <Task pending name='Task-7' coro=<main() running at C:\Users\club33\Desktop\RiseTGbot\main.py:47> wait_for=<Future pending cb...
           │    │     └ <function BaseEventLoop.run_until_complete at 0x00000290E79CF600>
           │    └ <ProactorEventLoop running=True closed=False debug=False>
           └ <asyncio.runners.Runner object at 0x00000290ECAB5790>
  File "c:\Users\club33\AppData\Local\Programs\Python\Python311\Lib\asyncio\base_events.py", line 641, in run_until_complete
    self.run_forever()
    │    └ <function ProactorEventLoop.run_forever at 0x00000290E7A51E40>
    └ <ProactorEventLoop running=True closed=False debug=False>
  File "c:\Users\club33\AppData\Local\Programs\Python\Python311\Lib\asyncio\windows_events.py", line 321, in run_forever
    super().run_forever()
  File "c:\Users\club33\AppData\Local\Programs\Python\Python311\Lib\asyncio\base_events.py", line 608, in run_forever
    self._run_once()
    │    └ <function BaseEventLoop._run_once at 0x00000290E79D53A0>
    └ <ProactorEventLoop running=True closed=False debug=False>
  File "c:\Users\club33\AppData\Local\Programs\Python\Python311\Lib\asyncio\base_events.py", line 1936, in _run_once
    handle._run()
    │      └ <function Handle._run at 0x00000290E7900C20>
    └ <Handle Task.task_wakeup(<Future finished result=None>)>
  File "c:\Users\club33\AppData\Local\Programs\Python\Python311\Lib\asyncio\events.py", line 84, in _run
    self._context.run(self._callback, *self._args)
    │    │            │    │           │    └ <member '_args' of 'Handle' objects>
    │    │            │    │           └ <Handle Task.task_wakeup(<Future finished result=None>)>
    │    │            │    └ <member '_callback' of 'Handle' objects>
    │    │            └ <Handle Task.task_wakeup(<Future finished result=None>)>
    │    └ <member '_context' of 'Handle' objects>
    └ <Handle Task.task_wakeup(<Future finished result=None>)>
> File "c:\Users\club33\AppData\Local\Programs\Python\Python311\Lib\site-packages\apscheduler\executors\base_py3.py", line 30, in run_coroutine_job
    retval = await job.func(*job.args, **job.kwargs)
                   │   │     │   │       │   └ <member 'kwargs' of 'Job' objects>
                   │   │     │   │       └ <Job (id=69c6ed59e28a4ea1aa3485a2e4920658 name=providers_items_update)>
                   │   │     │   └ <member 'args' of 'Job' objects>
                   │   │     └ <Job (id=69c6ed59e28a4ea1aa3485a2e4920658 name=providers_items_update)>
                   │   └ <member 'func' of 'Job' objects>
                   └ <Job (id=69c6ed59e28a4ea1aa3485a2e4920658 name=providers_items_update)>

  File "C:\Users\club33\Desktop\RiseTGbot\bot\schedulers\providers_items_update.py", line 18, in providers_items_update
    pricing_providers = await _load_file('data/pricing_providers.json')
                              └ <function _load_file at 0x00000290F1139760>

  File "C:\Users\club33\Desktop\RiseTGbot\bot\schedulers\providers_items_update.py", line 31, in _load_file
    return orjson.loads(content)
           │      │     └ ''
           │      └ <built-in function loads>
           └ <module 'orjson' from 'c:\\Users\\club33\\AppData\\Local\\Programs\\Python\\Python311\\Lib\\site-packages\\orjson\\__init__.py'>

orjson.JSONDecodeError: Input is a zero-length, empty document: line 1 column 1 (char 0)
2024-07-03 10:43:41 | ERROR | __init__:exception:1524 | Job "providers_items_update (trigger: interval[0:00:10], next run at: 2024-07-03 10:43:51 MSK)" raised an exception
Traceback (most recent call last):

  File "c:\Users\club33\AppData\Local\Programs\Python\Python311\Lib\runpy.py", line 198, in _run_module_as_main
    return _run_code(code, main_globals, None,
           │         │     └ {'__name__': '__main__', '__doc__': None, '__package__': '', '__loader__': <_frozen_importlib_external.SourceFileLoader objec...
           │         └ <code object <module> at 0x00000290E429F890, file "c:\Users\club33\.vscode\extensions\ms-python.debugpy-2024.6.0-win32-x64\bu...
           └ <function _run_code at 0x00000290E445A160>
  File "c:\Users\club33\AppData\Local\Programs\Python\Python311\Lib\runpy.py", line 88, in _run_code
    exec(code, run_globals)
         │     └ {'__name__': '__main__', '__doc__': None, '__package__': '', '__loader__': <_frozen_importlib_external.SourceFileLoader objec...
         └ <code object <module> at 0x00000290E429F890, file "c:\Users\club33\.vscode\extensions\ms-python.debugpy-2024.6.0-win32-x64\bu...

  File "c:\Users\club33\.vscode\extensions\ms-python.debugpy-2024.6.0-win32-x64\bundled\libs\debugpy\adapter/../..\debugpy\launcher/../..\debugpy\__main__.py", line 39, in <module>
    cli.main()
    │   └ <function main at 0x00000290E6F52FC0>
    └ <module 'debugpy.server.cli' from 'c:\\Users\\club33\\.vscode\\extensions\\ms-python.debugpy-2024.6.0-win32-x64\\bundled\\lib...

  File "c:\Users\club33\.vscode\extensions\ms-python.debugpy-2024.6.0-win32-x64\bundled\libs\debugpy\adapter/../..\debugpy\launcher/../..\debugpy/..\debugpy\server\cli.py", line 430, in main
    run()
    └ <function run_file at 0x00000290E6F52D40>

  File "c:\Users\club33\.vscode\extensions\ms-python.debugpy-2024.6.0-win32-x64\bundled\libs\debugpy\adapter/../..\debugpy\launcher/../..\debugpy/..\debugpy\server\cli.py", line 284, in run_file
    runpy.run_path(target, run_name="__main__")
    │     │        └ 'C:\\Users\\club33\\Desktop\\RiseTGbot\\main.py'
    │     └ <function run_path at 0x00000290E6B6BF60>
    └ <module '_pydevd_bundle.pydevd_runpy' from 'c:\\Users\\club33\\.vscode\\extensions\\ms-python.debugpy-2024.6.0-win32-x64\\bun...

  File "c:\Users\club33\.vscode\extensions\ms-python.debugpy-2024.6.0-win32-x64\bundled\libs\debugpy\_vendored\pydevd\_pydevd_bundle\pydevd_runpy.py", line 321, in run_path
    return _run_module_code(code, init_globals, run_name,
           │                │     │             └ '__main__'
           │                │     └ None
           │                └ <code object <module> at 0x00000290E6F90990, file "C:\Users\club33\Desktop\RiseTGbot\main.py", line 1>
           └ <function _run_module_code at 0x00000290E6B6BBA0>

  File "c:\Users\club33\.vscode\extensions\ms-python.debugpy-2024.6.0-win32-x64\bundled\libs\debugpy\_vendored\pydevd\_pydevd_bundle\pydevd_runpy.py", line 135, in _run_module_code
    _run_code(code, mod_globals, init_globals,
    │         │     │            └ None
    │         │     └ {'__name__': '__main__', '__doc__': None, '__package__': '', '__loader__': None, '__spec__': None, '__file__': 'C:\\Users\\cl...
    │         └ <code object <module> at 0x00000290E6F90990, file "C:\Users\club33\Desktop\RiseTGbot\main.py", line 1>
    └ <function _run_code at 0x00000290E6B6B740>

  File "c:\Users\club33\.vscode\extensions\ms-python.debugpy-2024.6.0-win32-x64\bundled\libs\debugpy\_vendored\pydevd\_pydevd_bundle\pydevd_runpy.py", line 124, in _run_code
    exec(code, run_globals)
         │     └ {'__name__': '__main__', '__doc__': None, '__package__': '', '__loader__': None, '__spec__': None, '__file__': 'C:\\Users\\cl...
         └ <code object <module> at 0x00000290E6F90990, file "C:\Users\club33\Desktop\RiseTGbot\main.py", line 1>

  File "C:\Users\club33\Desktop\RiseTGbot\main.py", line 52, in <module>
    asyncio.run(main())
    │       │   └ <function main at 0x00000290F11393A0>
    │       └ <function run at 0x00000290E79600E0>
    └ <module 'asyncio' from 'c:\\Users\\club33\\AppData\\Local\\Programs\\Python\\Python311\\Lib\\asyncio\\__init__.py'>

  File "c:\Users\club33\AppData\Local\Programs\Python\Python311\Lib\asyncio\runners.py", line 190, in run
    return runner.run(main)
           │      │   └ <coroutine object main at 0x00000290E6FCBD30>
           │      └ <function Runner.run at 0x00000290E79D5D00>
           └ <asyncio.runners.Runner object at 0x00000290ECAB5790>
  File "c:\Users\club33\AppData\Local\Programs\Python\Python311\Lib\asyncio\runners.py", line 118, in run
    return self._loop.run_until_complete(task)
           │    │     │                  └ <Task pending name='Task-7' coro=<main() running at C:\Users\club33\Desktop\RiseTGbot\main.py:47> wait_for=<Future pending cb...
           │    │     └ <function BaseEventLoop.run_until_complete at 0x00000290E79CF600>
           │    └ <ProactorEventLoop running=True closed=False debug=False>
           └ <asyncio.runners.Runner object at 0x00000290ECAB5790>
  File "c:\Users\club33\AppData\Local\Programs\Python\Python311\Lib\asyncio\base_events.py", line 641, in run_until_complete
    self.run_forever()
    │    └ <function ProactorEventLoop.run_forever at 0x00000290E7A51E40>
    └ <ProactorEventLoop running=True closed=False debug=False>
  File "c:\Users\club33\AppData\Local\Programs\Python\Python311\Lib\asyncio\windows_events.py", line 321, in run_forever
    super().run_forever()
  File "c:\Users\club33\AppData\Local\Programs\Python\Python311\Lib\asyncio\base_events.py", line 608, in run_forever
    self._run_once()
    │    └ <function BaseEventLoop._run_once at 0x00000290E79D53A0>
    └ <ProactorEventLoop running=True closed=False debug=False>
  File "c:\Users\club33\AppData\Local\Programs\Python\Python311\Lib\asyncio\base_events.py", line 1936, in _run_once
    handle._run()
    │      └ <function Handle._run at 0x00000290E7900C20>
    └ <Handle Task.task_wakeup(<Future finished result=None>)>
  File "c:\Users\club33\AppData\Local\Programs\Python\Python311\Lib\asyncio\events.py", line 84, in _run
    self._context.run(self._callback, *self._args)
    │    │            │    │           │    └ <member '_args' of 'Handle' objects>
    │    │            │    │           └ <Handle Task.task_wakeup(<Future finished result=None>)>
    │    │            │    └ <member '_callback' of 'Handle' objects>
    │    │            └ <Handle Task.task_wakeup(<Future finished result=None>)>
    │    └ <member '_context' of 'Handle' objects>
    └ <Handle Task.task_wakeup(<Future finished result=None>)>
> File "c:\Users\club33\AppData\Local\Programs\Python\Python311\Lib\site-packages\apscheduler\executors\base_py3.py", line 30, in run_coroutine_job
    retval = await job.func(*job.args, **job.kwargs)
                   │   │     │   │       │   └ <member 'kwargs' of 'Job' objects>
                   │   │     │   │       └ <Job (id=69c6ed59e28a4ea1aa3485a2e4920658 name=providers_items_update)>
                   │   │     │   └ <member 'args' of 'Job' objects>
                   │   │     └ <Job (id=69c6ed59e28a4ea1aa3485a2e4920658 name=providers_items_update)>
                   │   └ <member 'func' of 'Job' objects>
                   └ <Job (id=69c6ed59e28a4ea1aa3485a2e4920658 name=providers_items_update)>

  File "C:\Users\club33\Desktop\RiseTGbot\bot\schedulers\providers_items_update.py", line 18, in providers_items_update
    pricing_providers = await _load_file('data/pricing_providers.json')
                              └ <function _load_file at 0x00000290F1139760>

  File "C:\Users\club33\Desktop\RiseTGbot\bot\schedulers\providers_items_update.py", line 31, in _load_file
    return orjson.loads(content)
           │      │     └ ''
           │      └ <built-in function loads>
           └ <module 'orjson' from 'c:\\Users\\club33\\AppData\\Local\\Programs\\Python\\Python311\\Lib\\site-packages\\orjson\\__init__.py'>

orjson.JSONDecodeError: Input is a zero-length, empty document: line 1 column 1 (char 0)
